<script src="js/rtian.js" ></script>
<meta charset="utf-8" />
<title>jQuery.readyException() | jQuery API中文文档(适用jQuery 1.0 - jQuery 3.0)</title>
  
<div id="content" >

<div class="inner" role="main">
<article id="post-4250" class="post-4250 post type-post status-publish format-standard hentry category-core category-96">
	<header class="entry-header">
		<h1 class="entry-title">jQuery.readyException()</h1>
		<hr>
				<div class="entry-meta">
			分类: <span class="category">
<a href="core.htm">核心</a></span>		</div><!-- .entry-meta -->
			</header><!-- .entry-header -->
	<div class="entry-content">
		<article id="jQuery-readyException1" class="entry method"><h2 class="section-title">
<span class="name">jQuery.readyException( error )</span><span class="returns">返回: 
<a href="types.htm#Selector">Selector</a></span>
</h2>
<div class="entry-wrapper">
<p class="desc"><strong>描述: </strong>处理包裹在<code>jQuery()</code>中函数同步抛出的错误。</p>
<ul class="signatures"><li class="signature">
<h4 class="name">
<span class="version-details">添加的版本: 
<a href="3.1.htm">3.1</a></span><a id="jQuery-readyException-error" href="#jQuery-readyException-error"><span class="icon-link"></span>jQuery.readyException( error )</a>
</h4>
<ul><li>
<div><strong>error</strong></div>
<div>类型: 
<a href="types.htm#Error">Error</a>
</div>
<div>包裹在<code>jQuery()</code>中函数抛出的一个错误。</div>
</li></ul>
</li></ul>
<div class="longdesc" id="entry-longdesc">
    <p>当包裹在<code>jQuery()</code>或<code>jQuery( document ).ready()</code>，或等效的函数中的函数同步抛出错误的时候，这个方法就会被触发。默认情况下，在一个超时，它重新抛出错误，因此它被记录在控制台中，并传递给<code>window.onerror</code>，而不是被静悄悄的吞噬。如果你想以不同的方式处理这种错误，可以覆盖此方法。</p>
  </div>
<section class="entry-examples" id="entry-examples"><header><h2>例子:</h2></header><div class="entry-example" id="example-0">
<p>传递接受到的错误给 <code>console.error</code>。</p>
<div class="syntaxhighlighter javascript">
	<table>
		<tbody>
			<tr>
				<td class="gutter">
						<div class="line n1">1</div>
						<div class="line n2">2</div>
						<div class="line n3">3</div>
				</td>
				<td class="code">
					<pre><div class="container"><div class="line"><code>jQuery.readyException = <span class="keyword">function</span>( error ) {</code></div></div><div class="container"><div class="line"><code>  console.error( error );</code></div></div><div class="container"><div class="line"><code>};</code></div></div></pre>
				</td>
			</tr>
		</tbody>
	</table>
</div>
</div></section>
</div></article>	</div><!-- .entry-content -->
</article>
</div>
  </div>
